{
    "registryname": "aether_transmuter_2",
    "localizedname": "Aether Transmuter",
    "parts": [
        {
            "x": -2,
            "y": 0,
            "z": 0,
            "elements": [
                "xtones:ztyl@2"
            ]
        },
        {
            "x": 2,
            "y": 0,
            "z": 0,
            "elements": [
                "xtones:ztyl@2"
            ]
        },
        {
            "x": -3,
            "y": -10,
            "z": 3,
            "elements": [
                "xtones:sync@14"
            ]
        },
        {
            "x": -2,
            "y": -10,
            "z": 3,
            "elements": [
                "xtones:glaxx@7"
            ]
        },
        {
            "x": -2,
            "y": -12,
            "z": 2,
            "elements": [
                "xtones:zyth@0"
            ]
        },
        {
            "x": -1,
            "y": -10,
            "z": 3,
            "elements": [
                "xtones:glaxx@7"
            ]
        },
        {
            "x": 0,
            "y": -10,
            "z": 3,
            "elements": [
                "xtones:zech@0"
            ]
        },
        {
            "x": 1,
            "y": -17,
            "z": 0,
            "elements": [
                "xtones:sync@14"
            ]
        },
        {
            "x": 1,
            "y": -10,
            "z": 3,
            "elements": [
                "xtones:glaxx@7"
            ]
        },
        {
            "x": -1,
            "y": -14,
            "z": 1,
            "elements": [
                "xtones:sync@14"
            ]
        },
        {
            "x": 2,
            "y": -10,
            "z": 3,
            "elements": [
                "xtones:glaxx@7"
            ]
        },
        {
            "x": -1,
            "y": -17,
            "z": 0,
            "elements": [
                "xtones:sync@14"
            ]
        },
        {
            "x": 3,
            "y": -10,
            "z": 3,
            "elements": [
                "xtones:sync@14"
            ]
        },
        {
            "x": 2,
            "y": -12,
            "z": 2,
            "elements": [
                "xtones:zyth@0"
            ]
        },
        {
            "x": 1,
            "y": -14,
            "z": 1,
            "elements": [
                "xtones:sync@14"
            ]
        },
        {
            "x": 0,
            "y": -11,
            "z": -5,
            "elements": [
                "xtones:zech@7"
            ]
        },
        {
            "x": 0,
            "y": -7,
            "z": -3,
            "elements": [
                "xtones:sync@14"
            ]
        },
        {
            "x": 3,
            "y": -1,
            "z": 0,
            "elements": [
                "xtones:zech@7"
            ]
        },
        {
            "x": 0,
            "y": -5,
            "z": -2,
            "elements": [
                "xtones:zech@0"
            ]
        },
        {
            "x": 2,
            "y": -1,
            "z": 0,
            "elements": [
                "xtones:glaxx@7"
            ]
        },
        {
            "x": 1,
            "y": -1,
            "z": 0,
            "elements": [
                "xtones:glaxx@7"
            ]
        },
        {
            "x": 0,
            "y": -1,
            "z": 0,
            "elements": [
                "xtones:zech@7"
            ]
        },
        {
            "x": 0,
            "y": 1,
            "z": 0,
            "elements": [
                "xtones:zyth@8"
            ]
        },
        {
            "x": -1,
            "y": -1,
            "z": 0,
            "elements": [
                "xtones:glaxx@7"
            ]
        },
        {
            "x": -2,
            "y": -1,
            "z": 0,
            "elements": [
                "xtones:glaxx@7"
            ]
        },
        {
            "x": -3,
            "y": -1,
            "z": 0,
            "elements": [
                "xtones:zech@7"
            ]
        },
        {
            "x": 0,
            "y": -9,
            "z": 3,
            "elements": [
                "xtones:sync@14"
            ]
        },
        {
            "x": 0,
            "y": -18,
            "z": 0,
            "elements": [
                "xtones:sync@14"
            ]
        },
        {
            "x": 6,
            "y": -2,
            "z": 0,
            "elements": [
                "xtones:sync@14"
            ]
        },
        {
            "x": 5,
            "y": -2,
            "z": 0,
            "elements": [
                "xtones:sync@14"
            ]
        },
        {
            "x": 4,
            "y": -2,
            "z": 0,
            "elements": [
                "xtones:sync@14"
            ]
        },
        {
            "x": 0,
            "y": -10,
            "z": -4,
            "elements": [
                "xtones:sync@14"
            ]
        },
        {
            "x": 0,
            "y": -8,
            "z": -3,
            "elements": [
                "xtones:sync@14"
            ]
        },
        {
            "x": 3,
            "y": -2,
            "z": 0,
            "elements": [
                "modularmachinery:blockenergyinputhatch@4"
            ]
        },
        {
            "x": 0,
            "y": -2,
            "z": 0,
            "elements": [
                "xtones:bitt@8"
            ]
        },
        {
            "x": -3,
            "y": -2,
            "z": 0,
            "elements": [
                "modularmachinery:blockfluidinputhatch@5"
            ]
        },
        {
            "x": -4,
            "y": -2,
            "z": 0,
            "elements": [
                "xtones:sync@14"
            ]
        },
        {
            "x": -5,
            "y": -2,
            "z": 0,
            "elements": [
                "xtones:sync@14"
            ]
        },
        {
            "x": -6,
            "y": -2,
            "z": 0,
            "elements": [
                "xtones:sync@14"
            ]
        },
        {
            "x": 0,
            "y": -2,
            "z": 6,
            "elements": [
                "xtones:sync@14"
            ]
        },
        {
            "x": -3,
            "y": -10,
            "z": 2,
            "elements": [
                "xtones:glaxx@7"
            ]
        },
        {
            "x": -2,
            "y": -10,
            "z": 2,
            "elements": [
                "xtones:zech@0"
            ]
        },
        {
            "x": 0,
            "y": -8,
            "z": 3,
            "elements": [
                "xtones:sync@14"
            ]
        },
        {
            "x": 0,
            "y": -19,
            "z": 0,
            "elements": [
                "xtones:sync@14"
            ]
        },
        {
            "x": 2,
            "y": -10,
            "z": 2,
            "elements": [
                "xtones:zech@0"
            ]
        },
        {
            "x": 3,
            "y": -10,
            "z": 2,
            "elements": [
                "xtones:glaxx@7"
            ]
        },
        {
            "x": 4,
            "y": -11,
            "z": -4,
            "elements": [
                "xtones:zech@7"
            ]
        },
        {
            "x": 2,
            "y": -7,
            "z": -2,
            "elements": [
                "xtones:sync@14"
            ]
        },
        {
            "x": 0,
            "y": -11,
            "z": -4,
            "elements": [
                "xtones:zech@0"
            ]
        },
        {
            "x": 3,
            "y": -3,
            "z": 0,
            "elements": [
                "xtones:zech@0"
            ]
        },
        {
            "x": 0,
            "y": -9,
            "z": -3,
            "elements": [
                "xtones:sync@14"
            ]
        },
        {
            "x": -4,
            "y": -11,
            "z": -4,
            "elements": [
                "xtones:zech@7"
            ]
        },
        {
            "x": -2,
            "y": -7,
            "z": -2,
            "elements": [
                "xtones:sync@14"
            ]
        },
        {
            "x": -3,
            "y": -3,
            "z": 0,
            "elements": [
                "xtones:zech@0"
            ]
        },
        {
            "x": -2,
            "y": -9,
            "z": 2,
            "elements": [
                "xtones:sync@14"
            ]
        },
        {
            "x": 0,
            "y": -7,
            "z": 3,
            "elements": [
                "xtones:sync@14"
            ]
        },
        {
            "x": 2,
            "y": -9,
            "z": 2,
            "elements": [
                "xtones:sync@14"
            ]
        },
        {
            "x": 3,
            "y": -10,
            "z": -3,
            "elements": [
                "xtones:sync@14"
            ]
        },
        {
            "x": 2,
            "y": -10,
            "z": -3,
            "elements": [
                "xtones:glaxx@7"
            ]
        },
        {
            "x": 2,
            "y": -8,
            "z": -2,
            "elements": [
                "xtones:sync@14"
            ]
        },
        {
            "x": 1,
            "y": -10,
            "z": -3,
            "elements": [
                "xtones:glaxx@7"
            ]
        },
        {
            "x": 0,
            "y": -10,
            "z": -3,
            "elements": [
                "xtones:zech@0"
            ]
        },
        {
            "x": -1,
            "y": -10,
            "z": -3,
            "elements": [
                "xtones:glaxx@7"
            ]
        },
        {
            "x": 2,
            "y": -4,
            "z": 0,
            "elements": [
                "xtones:zech@0"
            ]
        },
        {
            "x": -2,
            "y": -10,
            "z": -3,
            "elements": [
                "xtones:glaxx@7"
            ]
        },
        {
            "x": 0,
            "y": -6,
            "z": -1,
            "elements": [
                "xtones:glaxx@7"
            ]
        },
        {
            "x": -3,
            "y": -10,
            "z": -3,
            "elements": [
                "xtones:sync@14"
            ]
        },
        {
            "x": -2,
            "y": -8,
            "z": -2,
            "elements": [
                "xtones:sync@14"
            ]
        },
        {
            "x": 0,
            "y": -4,
            "z": 0,
            "elements": [
                "xtones:zome@8"
            ]
        },
        {
            "x": -2,
            "y": -4,
            "z": 0,
            "elements": [
                "xtones:zech@0"
            ]
        },
        {
            "x": -5,
            "y": -2,
            "z": 5,
            "elements": [
                "xtones:sync@14"
            ]
        },
        {
            "x": 0,
            "y": -2,
            "z": 5,
            "elements": [
                "xtones:sync@14"
            ]
        },
        {
            "x": -3,
            "y": -10,
            "z": 1,
            "elements": [
                "xtones:glaxx@7"
            ]
        },
        {
            "x": -2,
            "y": -8,
            "z": 2,
            "elements": [
                "xtones:sync@14"
            ]
        },
        {
            "x": 5,
            "y": -2,
            "z": 5,
            "elements": [
                "xtones:sync@14"
            ]
        },
        {
            "x": 2,
            "y": -8,
            "z": 2,
            "elements": [
                "xtones:sync@14"
            ]
        },
        {
            "x": 3,
            "y": -10,
            "z": 1,
            "elements": [
                "xtones:glaxx@7"
            ]
        },
        {
            "x": 3,
            "y": -11,
            "z": -3,
            "elements": [
                "xtones:zech@0"
            ]
        },
        {
            "x": 2,
            "y": -9,
            "z": -2,
            "elements": [
                "xtones:sync@14"
            ]
        },
        {
            "x": 2,
            "y": -5,
            "z": 0,
            "elements": [
                "xtones:zech@0"
            ]
        },
        {
            "x": -3,
            "y": -11,
            "z": -3,
            "elements": [
                "xtones:zech@0"
            ]
        },
        {
            "x": -2,
            "y": -9,
            "z": -2,
            "elements": [
                "xtones:sync@14"
            ]
        },
        {
            "x": 0,
            "y": -5,
            "z": 0,
            "elements": [
                "xtones:glaxx@7"
            ]
        },
        {
            "x": -2,
            "y": -5,
            "z": 0,
            "elements": [
                "xtones:zech@0"
            ]
        },
        {
            "x": -2,
            "y": -7,
            "z": 2,
            "elements": [
                "xtones:sync@14"
            ]
        },
        {
            "x": 0,
            "y": -9,
            "z": 1,
            "elements": [
                "xtones:ztyl@2"
            ]
        },
        {
            "x": 2,
            "y": -7,
            "z": 2,
            "elements": [
                "xtones:sync@14"
            ]
        },
        {
            "x": 3,
            "y": -10,
            "z": -2,
            "elements": [
                "xtones:glaxx@7"
            ]
        },
        {
            "x": 2,
            "y": -10,
            "z": -2,
            "elements": [
                "xtones:zech@0"
            ]
        },
        {
            "x": 0,
            "y": -12,
            "z": -3,
            "elements": [
                "xtones:zyth@0"
            ]
        },
        {
            "x": 1,
            "y": -6,
            "z": 0,
            "elements": [
                "xtones:glaxx@7"
            ]
        },
        {
            "x": -2,
            "y": -10,
            "z": -2,
            "elements": [
                "xtones:zech@0"
            ]
        },
        {
            "x": 0,
            "y": -6,
            "z": 0,
            "elements": [
                "xtones:zyth@8"
            ]
        },
        {
            "x": -3,
            "y": -10,
            "z": -2,
            "elements": [
                "xtones:glaxx@7"
            ]
        },
        {
            "x": -1,
            "y": -6,
            "z": 0,
            "elements": [
                "xtones:glaxx@7"
            ]
        },
        {
            "x": -4,
            "y": -2,
            "z": 4,
            "elements": [
                "xtones:sync@14"
            ]
        },
        {
            "x": 0,
            "y": -2,
            "z": -6,
            "elements": [
                "xtones:sync@14"
            ]
        },
        {
            "x": 0,
            "y": -2,
            "z": 4,
            "elements": [
                "xtones:sync@14"
            ]
        },
        {
            "x": 4,
            "y": -2,
            "z": 4,
            "elements": [
                "xtones:sync@14"
            ]
        },
        {
            "x": 3,
            "y": -7,
            "z": 0,
            "elements": [
                "xtones:sync@14"
            ]
        },
        {
            "x": 0,
            "y": -13,
            "z": -3,
            "elements": [
                "xtones:sync@14"
            ]
        },
        {
            "x": 0,
            "y": -9,
            "z": -1,
            "elements": [
                "xtones:ztyl@2"
            ]
        },
        {
            "x": 0,
            "y": -7,
            "z": 0,
            "elements": [
                "xtones:glaxx@7"
            ]
        },
        {
            "x": -3,
            "y": -7,
            "z": 0,
            "elements": [
                "xtones:sync@14"
            ]
        },
        {
            "x": 0,
            "y": -3,
            "z": 3,
            "elements": [
                "xtones:zech@0"
            ]
        },
        {
            "x": 0,
            "y": -5,
            "z": 2,
            "elements": [
                "xtones:zech@0"
            ]
        },
        {
            "x": 3,
            "y": -10,
            "z": -1,
            "elements": [
                "xtones:glaxx@7"
            ]
        },
        {
            "x": 2,
            "y": -12,
            "z": -2,
            "elements": [
                "xtones:zyth@0"
            ]
        },
        {
            "x": 3,
            "y": -8,
            "z": 0,
            "elements": [
                "xtones:sync@14"
            ]
        },
        {
            "x": -2,
            "y": -12,
            "z": -2,
            "elements": [
                "xtones:zyth@0"
            ]
        },
        {
            "x": 0,
            "y": -8,
            "z": 0,
            "elements": [
                "xtones:zech@7"
            ]
        },
        {
            "x": -3,
            "y": -10,
            "z": -1,
            "elements": [
                "xtones:glaxx@7"
            ]
        },
        {
            "x": -3,
            "y": -8,
            "z": 0,
            "elements": [
                "xtones:sync@14"
            ]
        },
        {
            "x": 5,
            "y": -2,
            "z": -5,
            "elements": [
                "xtones:sync@14"
            ]
        },
        {
            "x": 0,
            "y": -2,
            "z": -5,
            "elements": [
                "xtones:sync@14"
            ]
        },
        {
            "x": -3,
            "y": -2,
            "z": 3,
            "elements": [
                "xtones:sync@14"
            ]
        },
        {
            "x": 0,
            "y": -2,
            "z": 3,
            "elements": [
                "modularmachinery:blockoutputbus@5"
            ]
        },
        {
            "x": 0,
            "y": -4,
            "z": 2,
            "elements": [
                "xtones:zech@0"
            ]
        },
        {
            "x": 0,
            "y": -6,
            "z": 1,
            "elements": [
                "xtones:glaxx@7"
            ]
        },
        {
            "x": -5,
            "y": -2,
            "z": -5,
            "elements": [
                "xtones:sync@14"
            ]
        },
        {
            "x": 3,
            "y": -2,
            "z": 3,
            "elements": [
                "xtones:sync@14"
            ]
        },
        {
            "x": 2,
            "y": -13,
            "z": -2,
            "elements": [
                "xtones:sync@14"
            ]
        },
        {
            "x": 3,
            "y": -9,
            "z": 0,
            "elements": [
                "xtones:sync@14"
            ]
        },
        {
            "x": 1,
            "y": -9,
            "z": 0,
            "elements": [
                "xtones:ztyl@2"
            ]
        },
        {
            "x": -2,
            "y": -13,
            "z": -2,
            "elements": [
                "xtones:sync@14"
            ]
        },
        {
            "x": 0,
            "y": -9,
            "z": 0,
            "elements": [
                "xtones:ztyl@2"
            ]
        },
        {
            "x": -1,
            "y": -9,
            "z": 0,
            "elements": [
                "xtones:ztyl@2"
            ]
        },
        {
            "x": -3,
            "y": -9,
            "z": 0,
            "elements": [
                "xtones:sync@14"
            ]
        },
        {
            "x": 0,
            "y": -1,
            "z": 3,
            "elements": [
                "xtones:zech@7"
            ]
        },
        {
            "x": 4,
            "y": -10,
            "z": 0,
            "elements": [
                "xtones:sync@14"
            ]
        },
        {
            "x": 3,
            "y": -10,
            "z": 0,
            "elements": [
                "xtones:zech@0"
            ]
        },
        {
            "x": 0,
            "y": -14,
            "z": -2,
            "elements": [
                "xtones:sync@14"
            ]
        },
        {
            "x": -3,
            "y": -10,
            "z": 0,
            "elements": [
                "xtones:zech@0"
            ]
        },
        {
            "x": -4,
            "y": -10,
            "z": 0,
            "elements": [
                "xtones:sync@14"
            ]
        },
        {
            "x": 4,
            "y": -2,
            "z": -4,
            "elements": [
                "xtones:sync@14"
            ]
        },
        {
            "x": 0,
            "y": -2,
            "z": -4,
            "elements": [
                "xtones:sync@14"
            ]
        },
        {
            "x": -2,
            "y": -2,
            "z": 2,
            "elements": [
                "xtones:ztyl@2"
            ]
        },
        {
            "x": -4,
            "y": -2,
            "z": -4,
            "elements": [
                "xtones:sync@14"
            ]
        },
        {
            "x": 2,
            "y": -2,
            "z": 2,
            "elements": [
                "xtones:ztyl@2"
            ]
        },
        {
            "x": 5,
            "y": -11,
            "z": 0,
            "elements": [
                "xtones:zech@7"
            ]
        },
        {
            "x": 4,
            "y": -11,
            "z": 0,
            "elements": [
                "xtones:zech@0"
            ]
        },
        {
            "x": 0,
            "y": -15,
            "z": -2,
            "elements": [
                "xtones:sync@14"
            ]
        },
        {
            "x": -4,
            "y": -11,
            "z": 0,
            "elements": [
                "xtones:zech@0"
            ]
        },
        {
            "x": -5,
            "y": -11,
            "z": 0,
            "elements": [
                "xtones:zech@7"
            ]
        },
        {
            "x": 0,
            "y": -1,
            "z": -3,
            "elements": [
                "xtones:zech@7"
            ]
        },
        {
            "x": -2,
            "y": -1,
            "z": 2,
            "elements": [
                "xtones:zech@7"
            ]
        },
        {
            "x": 0,
            "y": -1,
            "z": 2,
            "elements": [
                "xtones:glaxx@7"
            ]
        },
        {
            "x": 2,
            "y": -1,
            "z": 2,
            "elements": [
                "xtones:zech@7"
            ]
        },
        {
            "x": 0,
            "y": -11,
            "z": 5,
            "elements": [
                "xtones:zech@7"
            ]
        },
        {
            "x": 3,
            "y": -12,
            "z": 0,
            "elements": [
                "xtones:zyth@0"
            ]
        },
        {
            "x": 1,
            "y": -14,
            "z": -1,
            "elements": [
                "xtones:sync@14"
            ]
        },
        {
            "x": -1,
            "y": -14,
            "z": -1,
            "elements": [
                "xtones:sync@14"
            ]
        },
        {
            "x": -3,
            "y": -12,
            "z": 0,
            "elements": [
                "xtones:zyth@0"
            ]
        },
        {
            "x": 3,
            "y": -2,
            "z": -3,
            "elements": [
                "xtones:sync@14"
            ]
        },
        {
            "x": 0,
            "y": -2,
            "z": -3,
            "elements": [
                "modularmachinery:blockinputbus@5"
            ]
        },
        {
            "x": 0,
            "y": 0,
            "z": -2,
            "elements": [
                "xtones:ztyl@2"
            ]
        },
        {
            "x": 0,
            "y": 0,
            "z": 2,
            "elements": [
                "xtones:ztyl@2"
            ]
        },
        {
            "x": -3,
            "y": -2,
            "z": -3,
            "elements": [
                "xtones:sync@14"
            ]
        },
        {
            "x": 3,
            "y": -13,
            "z": 0,
            "elements": [
                "xtones:sync@14"
            ]
        },
        {
            "x": 1,
            "y": -15,
            "z": -1,
            "elements": [
                "xtones:sync@14"
            ]
        },
        {
            "x": -1,
            "y": -15,
            "z": -1,
            "elements": [
                "xtones:sync@14"
            ]
        },
        {
            "x": -3,
            "y": -13,
            "z": 0,
            "elements": [
                "xtones:sync@14"
            ]
        },
        {
            "x": 2,
            "y": -1,
            "z": -2,
            "elements": [
                "xtones:zech@7"
            ]
        },
        {
            "x": 0,
            "y": -3,
            "z": -3,
            "elements": [
                "xtones:zech@0"
            ]
        },
        {
            "x": 0,
            "y": -1,
            "z": -2,
            "elements": [
                "xtones:glaxx@7"
            ]
        },
        {
            "x": -1,
            "y": -1,
            "z": 1,
            "elements": [
                "xtones:glaxx@7"
            ]
        },
        {
            "x": 0,
            "y": -1,
            "z": 1,
            "elements": [
                "xtones:glaxx@7"
            ]
        },
        {
            "x": -2,
            "y": -1,
            "z": -2,
            "elements": [
                "xtones:zech@7"
            ]
        },
        {
            "x": 1,
            "y": -1,
            "z": 1,
            "elements": [
                "xtones:glaxx@7"
            ]
        },
        {
            "x": -4,
            "y": -11,
            "z": 4,
            "elements": [
                "xtones:zech@7"
            ]
        },
        {
            "x": 0,
            "y": -11,
            "z": 4,
            "elements": [
                "xtones:zech@0"
            ]
        },
        {
            "x": 2,
            "y": -14,
            "z": 0,
            "elements": [
                "xtones:sync@14"
            ]
        },
        {
            "x": 0,
            "y": -13,
            "z": 3,
            "elements": [
                "xtones:sync@14"
            ]
        },
        {
            "x": 0,
            "y": -16,
            "z": -1,
            "elements": [
                "xtones:sync@14"
            ]
        },
        {
            "x": 0,
            "y": -15,
            "z": 2,
            "elements": [
                "xtones:sync@14"
            ]
        },
        {
            "x": 0,
            "y": -17,
            "z": 1,
            "elements": [
                "xtones:sync@14"
            ]
        },
        {
            "x": -2,
            "y": -14,
            "z": 0,
            "elements": [
                "xtones:sync@14"
            ]
        },
        {
            "x": 4,
            "y": -11,
            "z": 4,
            "elements": [
                "xtones:zech@7"
            ]
        },
        {
            "x": 2,
            "y": -2,
            "z": -2,
            "elements": [
                "xtones:ztyl@2"
            ]
        },
        {
            "x": 1,
            "y": 0,
            "z": -1,
            "elements": [
                "xtones:ztyl@2"
            ]
        },
        {
            "x": -1,
            "y": 0,
            "z": 1,
            "elements": [
                "xtones:ztyl@2"
            ]
        },
        {
            "x": -2,
            "y": -2,
            "z": -2,
            "elements": [
                "xtones:ztyl@2"
            ]
        },
        {
            "x": -1,
            "y": 0,
            "z": -1,
            "elements": [
                "xtones:ztyl@2"
            ]
        },
        {
            "x": 1,
            "y": 0,
            "z": 1,
            "elements": [
                "xtones:ztyl@2"
            ]
        },
        {
            "x": 0,
            "y": -10,
            "z": 4,
            "elements": [
                "xtones:sync@14"
            ]
        },
        {
            "x": 2,
            "y": -15,
            "z": 0,
            "elements": [
                "xtones:sync@14"
            ]
        },
        {
            "x": 0,
            "y": -17,
            "z": -1,
            "elements": [
                "xtones:sync@14"
            ]
        },
        {
            "x": 0,
            "y": -12,
            "z": 3,
            "elements": [
                "xtones:zyth@0"
            ]
        },
        {
            "x": 0,
            "y": -14,
            "z": 2,
            "elements": [
                "xtones:sync@14"
            ]
        },
        {
            "x": 0,
            "y": -16,
            "z": 1,
            "elements": [
                "xtones:sync@14"
            ]
        },
        {
            "x": -2,
            "y": -15,
            "z": 0,
            "elements": [
                "xtones:sync@14"
            ]
        },
        {
            "x": 1,
            "y": -1,
            "z": -1,
            "elements": [
                "xtones:glaxx@7"
            ]
        },
        {
            "x": 0,
            "y": -1,
            "z": -1,
            "elements": [
                "xtones:glaxx@7"
            ]
        },
        {
            "x": -1,
            "y": -1,
            "z": -1,
            "elements": [
                "xtones:glaxx@7"
            ]
        },
        {
            "x": -3,
            "y": -11,
            "z": 3,
            "elements": [
                "xtones:zech@0"
            ]
        },
        {
            "x": -2,
            "y": -13,
            "z": 2,
            "elements": [
                "xtones:sync@14"
            ]
        },
        {
            "x": 1,
            "y": -16,
            "z": 0,
            "elements": [
                "xtones:sync@14"
            ]
        },
        {
            "x": -1,
            "y": -15,
            "z": 1,
            "elements": [
                "xtones:sync@14"
            ]
        },
        {
            "x": -1,
            "y": -16,
            "z": 0,
            "elements": [
                "xtones:sync@14"
            ]
        },
        {
            "x": 3,
            "y": -11,
            "z": 3,
            "elements": [
                "xtones:zech@0"
            ]
        },
        {
            "x": 2,
            "y": -13,
            "z": 2,
            "elements": [
                "xtones:sync@14"
            ]
        },
        {
            "x": 1,
            "y": -15,
            "z": 1,
            "elements": [
                "xtones:sync@14"
            ]
        },
        {
            "x": 0,
            "y": -4,
            "z": -2,
            "elements": [
                "xtones:zech@0"
            ]
        }
    ]}