{
    "registryname": "demon_will_coagulator_2",
    "localizedname": "Demon Will Coagulator 2",
    "requires-blueprint": false,
	"color": "a13434",
    "parts": [
        {
            "x": -1,
            "y": 0,
            "z": 0,
            "elements": [
                "bloodmagic:demon_pillar_2@3"
            ]
        },
        {
            "x": 1,
            "y": 0,
            "z": 0,
            "elements": [
                "bloodmagic:demon_pillar_2@3"
            ]
        },
        {
            "x": -1,
            "y": 0,
            "z": 8,
            "elements": [
                "bloodmagic:demon_pillar_2@3"
            ]
        },
        {
            "x": -1,
            "y": -2,
            "z": 7,
            "elements": [
                "bloodmagic:demon_pillar_2@13"
            ]
        },
        {
            "x": -1,
            "y": -4,
            "z": 6,
            "elements": [
                "xtones:reds@5"
            ]
        },
        {
            "x": 1,
            "y": 0,
            "z": 8,
            "elements": [
                "bloodmagic:demon_pillar_2@3"
            ]
        },
        {
            "x": 1,
            "y": -2,
            "z": 7,
            "elements": [
                "bloodmagic:demon_pillar_2@13"
            ]
        },
        {
            "x": 2,
            "y": -4,
            "z": 6,
            "elements": [
                "xtones:reds@5"
            ]
        },
        {
            "x": 2,
            "y": -1,
            "z": 0,
            "elements": [
                "bloodmagic:demon_pillar_2@13"
            ]
        },
        {
            "x": 2,
            "y": 9,
            "z": 4,
            "elements": [
                "xtones:reds@5"
            ]
        },
        {
            "x": 0,
            "y": 5,
            "z": 2,
            "elements": [
                "xtones:reds@5"
            ]
        },
        {
            "x": 1,
            "y": -1,
            "z": 0,
            "elements": [
                "xtones:glaxx@11"
            ]
        },
        {
            "x": 0,
            "y": -1,
            "z": 0,
            "elements": [
                "bloodmagic:demon_brick_2@13"
            ]
        },
        {
            "x": -1,
            "y": 1,
            "z": 0,
            "elements": [
                "bloodmagic:demon_pillar_2@3"
            ]
        },
        {
            "x": -1,
            "y": -1,
            "z": 0,
            "elements": [
                "xtones:glaxx@11"
            ]
        },
        {
            "x": -2,
            "y": -1,
            "z": 0,
            "elements": [
                "bloodmagic:demon_pillar_2@13"
            ]
        },
        {
            "x": 1,
            "y": 1,
            "z": 0,
            "elements": [
                "bloodmagic:demon_pillar_2@3"
            ]
        },
        {
            "x": -3,
            "y": -1,
            "z": 7,
            "elements": [
                "bloodmagic:demon_brick_2@13"
            ]
        },
        {
            "x": -2,
            "y": -1,
            "z": 7,
            "elements": [
                "xtones:korp@2"
            ]
        },
        {
            "x": -1,
            "y": 1,
            "z": 8,
            "elements": [
                "bloodmagic:demon_pillar_2@3"
            ]
        },
        {
            "x": -1,
            "y": -1,
            "z": 7,
            "elements": [
                "xtones:reds@14"
            ]
        },
        {
            "x": -1,
            "y": -3,
            "z": 6,
            "elements": [
                "xtones:reds@5"
            ]
        },
        {
            "x": 0,
            "y": -1,
            "z": 7,
            "elements": [
                "xtones:reds@14"
            ]
        },
        {
            "x": 1,
            "y": 1,
            "z": 8,
            "elements": [
                "bloodmagic:demon_pillar_2@3"
            ]
        },
        {
            "x": 1,
            "y": -1,
            "z": 7,
            "elements": [
                "xtones:reds@6"
            ]
        },
        {
            "x": 2,
            "y": -1,
            "z": 7,
            "elements": [
                "xtones:reds@14"
            ]
        },
        {
            "x": 3,
            "y": -1,
            "z": 7,
            "elements": [
                "bloodmagic:demon_brick_2@13"
            ]
        },
        {
            "x": 2,
            "y": -3,
            "z": 6,
            "elements": [
                "xtones:reds@5"
            ]
        },
        {
            "x": 0,
            "y": 14,
            "z": 6,
            "elements": [
                "xtones:reds@15"
            ]
        },
        {
            "x": 2,
            "y": 10,
            "z": 4,
            "elements": [
                "xtones:reds@5"
            ]
        },
        {
            "x": 0,
            "y": 6,
            "z": 2,
            "elements": [
                "xtones:reds@5"
            ]
        },
        {
            "x": 1,
            "y": -2,
            "z": 0,
            "elements": [
                "bloodmagic:demon_pillar_2@13"
            ]
        },
        {
            "x": 0,
            "y": 2,
            "z": 0,
            "elements": [
                "bloodmagic:demon_brick_2@13"
            ]
        },
        {
            "x": -1,
            "y": -2,
            "z": 0,
            "elements": [
                "bloodmagic:demon_pillar_2@13"
            ]
        },
        {
            "x": 0,
            "y": 2,
            "z": 8,
            "elements": [
                "bloodmagic:demon_brick_2@13"
            ]
        },
        {
            "x": -1,
            "y": -2,
            "z": 6,
            "elements": [
                "xtones:reds@4"
            ]
        },
        {
            "x": 2,
            "y": -2,
            "z": 6,
            "elements": [
                "xtones:reds@4"
            ]
        },
        {
            "x": 0,
            "y": 15,
            "z": 6,
            "elements": [
                "xtones:reds@15"
            ]
        },
        {
            "x": 0,
            "y": 13,
            "z": 5,
            "elements": [
                "xtones:reds@15"
            ]
        },
        {
            "x": 2,
            "y": 11,
            "z": 4,
            "elements": [
                "xtones:reds@11"
            ]
        },
        {
            "x": 0,
            "y": 7,
            "z": 2,
            "elements": [
                "xtones:reds@5"
            ]
        },
        {
            "x": -4,
            "y": -1,
            "z": 6,
            "elements": [
                "bloodmagic:demon_pillar_2@8"
            ]
        },
        {
            "x": -3,
            "y": -1,
            "z": 6,
            "elements": [
                "xtones:korp@2"
            ]
        },
        {
            "x": -2,
            "y": -1,
            "z": 6,
            "elements": [
                "xtones:reds@13"
            ]
        },
        {
            "x": -1,
            "y": -1,
            "z": 6,
            "elements": [
                "xtones:ztyl@2"
            ]
        },
        {
            "x": 0,
            "y": -1,
            "z": 6,
            "elements": [
                "xtones:ztyl@2"
            ]
        },
        {
            "x": -2,
            "y": -7,
            "z": 3,
            "elements": [
                "xtones:reds@8"
            ]
        },
        {
            "x": 1,
            "y": -1,
            "z": 6,
            "elements": [
                "xtones:reds@6"
            ]
        },
        {
            "x": 0,
            "y": -5,
            "z": 4,
            "elements": [
                "bloodmagic:demon_brick_2@13"
            ]
        },
        {
            "x": 2,
            "y": -1,
            "z": 6,
            "elements": [
                "xtones:reds@13"
            ]
        },
        {
            "x": 3,
            "y": -1,
            "z": 6,
            "elements": [
                "xtones:reds@14"
            ]
        },
        {
            "x": 4,
            "y": -1,
            "z": 6,
            "elements": [
                "bloodmagic:demon_pillar_2@8"
            ]
        },
        {
            "x": 0,
            "y": 16,
            "z": 6,
            "elements": [
                "xtones:reds@15"
            ]
        },
        {
            "x": 0,
            "y": 14,
            "z": 5,
            "elements": [
                "xtones:glaxx@11"
            ]
        },
        {
            "x": 0,
            "y": 12,
            "z": 4,
            "elements": [
                "xtones:reds@15"
            ]
        },
        {
            "x": 0,
            "y": 8,
            "z": 2,
            "elements": [
                "xtones:reds@5"
            ]
        },
        {
            "x": -5,
            "y": -2,
            "z": 5,
            "elements": [
                "bloodmagic:demon_brick_2@13"
            ]
        },
        {
            "x": -4,
            "y": -2,
            "z": 5,
            "elements": [
                "bloodmagic:demon_pillar_2@8"
            ]
        },
        {
            "x": -3,
            "y": -2,
            "z": 5,
            "elements": [
                "bloodmagic:demon_pillar_2@8"
            ]
        },
        {
            "x": -2,
            "y": -2,
            "z": 5,
            "elements": [
                "bloodmagic:demon_pillar_2@8"
            ]
        },
        {
            "x": -2,
            "y": -6,
            "z": 3,
            "elements": [
                "xtones:reds@5"
            ]
        },
        {
            "x": 0,
            "y": -2,
            "z": 5,
            "elements": [
                "bloodmagic:demon_pillar_2@3"
            ]
        },
        {
            "x": 0,
            "y": -4,
            "z": 4,
            "elements": [
                "bloodmagic:demon_pillar_2@3"
            ]
        },
        {
            "x": 1,
            "y": -2,
            "z": 5,
            "elements": [
                "xtones:glaxx@11"
            ]
        },
        {
            "x": 2,
            "y": -2,
            "z": 5,
            "elements": [
                "bloodmagic:demon_pillar_2@8"
            ]
        },
        {
            "x": 3,
            "y": -2,
            "z": 5,
            "elements": [
                "bloodmagic:demon_pillar_2@8"
            ]
        },
        {
            "x": 4,
            "y": -2,
            "z": 5,
            "elements": [
                "bloodmagic:demon_pillar_2@8"
            ]
        },
        {
            "x": 5,
            "y": -2,
            "z": 5,
            "elements": [
                "bloodmagic:demon_brick_2@13"
            ]
        },
        {
            "x": -1,
            "y": 13,
            "z": 4,
            "elements": [
                "xtones:reds@15"
            ]
        },
        {
            "x": 0,
            "y": 15,
            "z": 5,
            "elements": [
                "xtones:glaxx@11"
            ]
        },
        {
            "x": 0,
            "y": 13,
            "z": 4,
            "elements": [
                "xtones:reds@14"
            ]
        },
        {
            "x": 1,
            "y": 13,
            "z": 4,
            "elements": [
                "xtones:reds@15"
            ]
        },
        {
            "x": 0,
            "y": 9,
            "z": 2,
            "elements": [
                "xtones:reds@11"
            ]
        },
        {
            "x": -8,
            "y": -1,
            "z": 5,
            "elements": [
                "xtones:glaxx@11"
            ]
        },
        {
            "x": -7,
            "y": -1,
            "z": 5,
            "elements": [
                "xtones:glaxx@11"
            ]
        },
        {
            "x": -6,
            "y": -1,
            "z": 5,
            "elements": [
                "xtones:glaxx@11"
            ]
        },
        {
            "x": -5,
            "y": -1,
            "z": 5,
            "elements": [
                "xtones:glaxx@11"
            ]
        },
        {
            "x": -4,
            "y": -1,
            "z": 5,
            "elements": [
                "xtones:glaxx@11"
            ]
        },
        {
            "x": -3,
            "y": -1,
            "z": 5,
            "elements": [
                "xtones:reds@5"
            ]
        },
        {
            "x": -2,
            "y": -1,
            "z": 5,
            "elements": [
                "xtones:reds@5"
            ]
        },
        {
            "x": 0,
            "y": 1,
            "z": 6,
            "elements": [
                "xtones:zyth@13"
            ]
        },
        {
            "x": -1,
            "y": -1,
            "z": 5,
            "elements": [
                "xtones:reds@11"
            ]
        },
        {
            "x": -2,
            "y": -5,
            "z": 3,
            "elements": [
                "xtones:reds@5"
            ]
        },
        {
            "x": 0,
            "y": -1,
            "z": 5,
            "elements": [
                "xtones:reds@11"
            ]
        },
        {
            "x": 0,
            "y": -3,
            "z": 4,
            "elements": [
                "bloodmagic:demon_pillar_2@3"
            ]
        },
        {
            "x": 1,
            "y": -1,
            "z": 5,
            "elements": [
                "xtones:reds@11"
            ]
        },
        {
            "x": 2,
            "y": -1,
            "z": 5,
            "elements": [
                "xtones:ztyl@2"
            ]
        },
        {
            "x": 3,
            "y": -1,
            "z": 5,
            "elements": [
                "xtones:reds@14"
            ]
        },
        {
            "x": 4,
            "y": -1,
            "z": 5,
            "elements": [
                "xtones:glaxx@11"
            ]
        },
        {
            "x": 5,
            "y": -1,
            "z": 5,
            "elements": [
                "xtones:glaxx@11"
            ]
        },
        {
            "x": 3,
            "y": -5,
            "z": 3,
            "elements": [
                "xtones:reds@8"
            ]
        },
        {
            "x": 6,
            "y": -1,
            "z": 5,
            "elements": [
                "xtones:glaxx@11"
            ]
        },
        {
            "x": 1,
            "y": -1,
            "z": 13,
            "elements": [
                "xtones:glaxx@11"
            ]
        },
        {
            "x": -2,
            "y": 14,
            "z": 4,
            "elements": [
                "xtones:reds@15"
            ]
        },
        {
            "x": -1,
            "y": 14,
            "z": 4,
            "elements": [
                "xtones:glaxx@11"
            ]
        },
        {
            "x": 0,
            "y": 16,
            "z": 5,
            "elements": [
                "xtones:glaxx@11"
            ]
        },
        {
            "x": 0,
            "y": 14,
            "z": 4,
            "elements": [
                "xtones:reds@14"
            ]
        },
        {
            "x": 1,
            "y": 14,
            "z": 4,
            "elements": [
                "xtones:glaxx@11"
            ]
        },
        {
            "x": 2,
            "y": 14,
            "z": 4,
            "elements": [
                "xtones:reds@15"
            ]
        },
        {
            "x": -4,
            "y": 0,
            "z": 5,
            "elements": [
                "bloodmagic:demon_pillar_2@3"
            ]
        },
        {
            "x": 0,
            "y": 2,
            "z": 6,
            "elements": [
                "xtones:reds@5"
            ]
        },
        {
            "x": -2,
            "y": -4,
            "z": 3,
            "elements": [
                "xtones:reds@5"
            ]
        },
        {
            "x": -1,
            "y": -2,
            "z": 4,
            "elements": [
                "bloodmagic:demon_pillar_2@3"
            ]
        },
        {
            "x": 0,
            "y": -2,
            "z": 4,
            "elements": [
                "bloodmagic:demon_pillar_2@3"
            ]
        },
        {
            "x": 1,
            "y": -2,
            "z": 4,
            "elements": [
                "bloodmagic:demon_pillar_2@3"
            ]
        },
        {
            "x": 4,
            "y": 0,
            "z": 5,
            "elements": [
                "bloodmagic:demon_pillar_2@3"
            ]
        },
        {
            "x": 3,
            "y": -4,
            "z": 3,
            "elements": [
                "xtones:reds@5"
            ]
        },
        {
            "x": -2,
            "y": 15,
            "z": 4,
            "elements": [
                "xtones:reds@15"
            ]
        },
        {
            "x": 0,
            "y": 17,
            "z": 5,
            "elements": [
                "xtones:reds@15"
            ]
        },
        {
            "x": -1,
            "y": 15,
            "z": 4,
            "elements": [
                "xtones:glaxx@11"
            ]
        },
        {
            "x": 0,
            "y": 15,
            "z": 4,
            "elements": [
                "xtones:ztyl@2"
            ]
        },
        {
            "x": 1,
            "y": 15,
            "z": 4,
            "elements": [
                "xtones:glaxx@11"
            ]
        },
        {
            "x": 0,
            "y": 13,
            "z": 3,
            "elements": [
                "xtones:reds@15"
            ]
        },
        {
            "x": 2,
            "y": 15,
            "z": 4,
            "elements": [
                "xtones:reds@15"
            ]
        },
        {
            "x": -4,
            "y": 1,
            "z": 5,
            "elements": [
                "bloodmagic:demon_pillar_2@3"
            ]
        },
        {
            "x": -4,
            "y": -1,
            "z": 4,
            "elements": [
                "bloodmagic:demon_brick_2@13"
            ]
        },
        {
            "x": -3,
            "y": -1,
            "z": 4,
            "elements": [
                "xtones:korp@2"
            ]
        },
        {
            "x": 0,
            "y": 3,
            "z": 6,
            "elements": [
                "xtones:reds@5"
            ]
        },
        {
            "x": -2,
            "y": -1,
            "z": 4,
            "elements": [
                "xtones:ztyl@2"
            ]
        },
        {
            "x": -2,
            "y": -3,
            "z": 3,
            "elements": [
                "xtones:reds@5"
            ]
        },
        {
            "x": -1,
            "y": -1,
            "z": 4,
            "elements": [
                "xtones:reds@11"
            ]
        },
        {
            "x": 0,
            "y": -1,
            "z": 4,
            "elements": [
                "modularmachinery:blockoutputbus"
            ]
        },
        {
            "x": 1,
            "y": -1,
            "z": 4,
            "elements": [
                "xtones:reds@11"
            ]
        },
        {
            "x": 2,
            "y": -1,
            "z": 4,
            "elements": [
                "xtones:ztyl@2"
            ]
        },
        {
            "x": 4,
            "y": 1,
            "z": 5,
            "elements": [
                "bloodmagic:demon_pillar_2@3"
            ]
        },
        {
            "x": 3,
            "y": -1,
            "z": 4,
            "elements": [
                "xtones:reds@14"
            ]
        },
        {
            "x": 4,
            "y": -1,
            "z": 4,
            "elements": [
                "bloodmagic:demon_brick_2@13"
            ]
        },
        {
            "x": 3,
            "y": -3,
            "z": 3,
            "elements": [
                "xtones:reds@5"
            ]
        },
        {
            "x": 1,
            "y": -1,
            "z": 12,
            "elements": [
                "xtones:glaxx@11"
            ]
        },
        {
            "x": -2,
            "y": 16,
            "z": 4,
            "elements": [
                "xtones:reds@15"
            ]
        },
        {
            "x": -1,
            "y": 16,
            "z": 4,
            "elements": [
                "xtones:glaxx@11"
            ]
        },
        {
            "x": 0,
            "y": 16,
            "z": 4,
            "elements": [
                "xtones:reds@14"
            ]
        },
        {
            "x": 1,
            "y": 16,
            "z": 4,
            "elements": [
                "xtones:glaxx@11"
            ]
        },
        {
            "x": 0,
            "y": 14,
            "z": 3,
            "elements": [
                "xtones:glaxx@11"
            ]
        },
        {
            "x": 2,
            "y": 16,
            "z": 4,
            "elements": [
                "xtones:reds@15"
            ]
        },
        {
            "x": -5,
            "y": -2,
            "z": 3,
            "elements": [
                "bloodmagic:demon_brick_2@13"
            ]
        },
        {
            "x": -4,
            "y": -2,
            "z": 3,
            "elements": [
                "bloodmagic:demon_pillar_2@8"
            ]
        },
        {
            "x": 0,
            "y": 4,
            "z": 6,
            "elements": [
                "xtones:reds@5"
            ]
        },
        {
            "x": -3,
            "y": -2,
            "z": 3,
            "elements": [
                "bloodmagic:demon_pillar_2@8"
            ]
        },
        {
            "x": -2,
            "y": -2,
            "z": 3,
            "elements": [
                "xtones:reds@4"
            ]
        },
        {
            "x": -1,
            "y": -2,
            "z": 3,
            "elements": [
                "xtones:glaxx@11"
            ]
        },
        {
            "x": 0,
            "y": -2,
            "z": 3,
            "elements": [
                "bloodmagic:demon_pillar_2@3"
            ]
        },
        {
            "x": 3,
            "y": -2,
            "z": 3,
            "elements": [
                "xtones:reds@4"
            ]
        },
        {
            "x": 1,
            "y": -6,
            "z": 1,
            "elements": [
                "xtones:reds@8"
            ]
        },
        {
            "x": 4,
            "y": -2,
            "z": 3,
            "elements": [
                "bloodmagic:demon_pillar_2@8"
            ]
        },
        {
            "x": 5,
            "y": -2,
            "z": 3,
            "elements": [
                "bloodmagic:demon_brick_2@13"
            ]
        },
        {
            "x": 0,
            "y": 17,
            "z": 4,
            "elements": [
                "contenttweaker:demon_will_coagulator_2@0"
            ]
        },
        {
            "x": -1,
            "y": 17,
            "z": 4,
            "elements": [
                "xtones:reds@15"
            ]
        },
        {
            "x": 1,
            "y": 17,
            "z": 4,
            "elements": [
                "xtones:reds@15"
            ]
        },
        {
            "x": 0,
            "y": 15,
            "z": 3,
            "elements": [
                "xtones:glaxx@11"
            ]
        },
        {
            "x": -6,
            "y": -1,
            "z": 3,
            "elements": [
                "xtones:glaxx@11"
            ]
        },
        {
            "x": -5,
            "y": -1,
            "z": 3,
            "elements": [
                "xtones:glaxx@11"
            ]
        },
        {
            "x": -4,
            "y": -1,
            "z": 3,
            "elements": [
                "xtones:glaxx@11"
            ]
        },
        {
            "x": 0,
            "y": 5,
            "z": 6,
            "elements": [
                "xtones:reds@11"
            ]
        },
        {
            "x": -3,
            "y": -1,
            "z": 3,
            "elements": [
                "xtones:korp@2"
            ]
        },
        {
            "x": -2,
            "y": 1,
            "z": 4,
            "elements": [
                "xtones:zyth@13"
            ]
        },
        {
            "x": 1,
            "y": -1,
            "z": -4,
            "elements": [
                "xtones:glaxx@11"
            ]
        },
        {
            "x": -2,
            "y": -1,
            "z": 3,
            "elements": [
                "xtones:ztyl@2"
            ]
        },
        {
            "x": -1,
            "y": -1,
            "z": 3,
            "elements": [
                "xtones:reds@11"
            ]
        },
        {
            "x": 0,
            "y": -1,
            "z": 3,
            "elements": [
                "xtones:reds@11"
            ]
        },
        {
            "x": 2,
            "y": 1,
            "z": 4,
            "elements": [
                "xtones:zyth@13"
            ]
        },
        {
            "x": 1,
            "y": -1,
            "z": 3,
            "elements": [
                "xtones:reds@11"
            ]
        },
        {
            "x": 2,
            "y": -1,
            "z": 3,
            "elements": [
                "xtones:reds@5"
            ]
        },
        {
            "x": 3,
            "y": -1,
            "z": 3,
            "elements": [
                "xtones:reds@5"
            ]
        },
        {
            "x": 1,
            "y": -5,
            "z": 1,
            "elements": [
                "xtones:reds@5"
            ]
        },
        {
            "x": 4,
            "y": -1,
            "z": 3,
            "elements": [
                "xtones:glaxx@11"
            ]
        },
        {
            "x": 5,
            "y": -1,
            "z": 3,
            "elements": [
                "xtones:glaxx@11"
            ]
        },
        {
            "x": 6,
            "y": -1,
            "z": 3,
            "elements": [
                "xtones:glaxx@11"
            ]
        },
        {
            "x": 7,
            "y": -1,
            "z": 3,
            "elements": [
                "xtones:glaxx@11"
            ]
        },
        {
            "x": -1,
            "y": -1,
            "z": 11,
            "elements": [
                "xtones:glaxx@11"
            ]
        },
        {
            "x": 8,
            "y": -1,
            "z": 3,
            "elements": [
                "xtones:glaxx@11"
            ]
        },
        {
            "x": 1,
            "y": -1,
            "z": 11,
            "elements": [
                "xtones:glaxx@11"
            ]
        },
        {
            "x": 0,
            "y": 18,
            "z": 4,
            "elements": [
                "xtones:reds@15"
            ]
        },
        {
            "x": 0,
            "y": 16,
            "z": 3,
            "elements": [
                "xtones:glaxx@11"
            ]
        },
        {
            "x": 0,
            "y": 14,
            "z": 2,
            "elements": [
                "xtones:reds@15"
            ]
        },
        {
            "x": -4,
            "y": 2,
            "z": 4,
            "elements": [
                "bloodmagic:demon_brick_2@13"
            ]
        },
        {
            "x": -4,
            "y": 0,
            "z": 3,
            "elements": [
                "bloodmagic:demon_pillar_2@3"
            ]
        },
        {
            "x": -2,
            "y": 2,
            "z": 4,
            "elements": [
                "xtones:reds@5"
            ]
        },
        {
            "x": -1,
            "y": -2,
            "z": 2,
            "elements": [
                "bloodmagic:demon_pillar_2@13"
            ]
        },
        {
            "x": 2,
            "y": 2,
            "z": 4,
            "elements": [
                "xtones:reds@5"
            ]
        },
        {
            "x": 4,
            "y": 2,
            "z": 4,
            "elements": [
                "bloodmagic:demon_brick_2@13"
            ]
        },
        {
            "x": 1,
            "y": -4,
            "z": 1,
            "elements": [
                "xtones:reds@5"
            ]
        },
        {
            "x": 4,
            "y": 0,
            "z": 3,
            "elements": [
                "bloodmagic:demon_pillar_2@3"
            ]
        },
        {
            "x": 0,
            "y": 17,
            "z": 3,
            "elements": [
                "xtones:reds@15"
            ]
        },
        {
            "x": 0,
            "y": 15,
            "z": 2,
            "elements": [
                "xtones:reds@15"
            ]
        },
        {
            "x": -4,
            "y": 1,
            "z": 3,
            "elements": [
                "bloodmagic:demon_pillar_2@3"
            ]
        },
        {
            "x": -4,
            "y": -1,
            "z": 2,
            "elements": [
                "bloodmagic:demon_pillar_2@8"
            ]
        },
        {
            "x": -2,
            "y": 3,
            "z": 4,
            "elements": [
                "xtones:reds@5"
            ]
        },
        {
            "x": -3,
            "y": -1,
            "z": 2,
            "elements": [
                "xtones:korp@2"
            ]
        },
        {
            "x": 1,
            "y": -1,
            "z": -3,
            "elements": [
                "xtones:glaxx@11"
            ]
        },
        {
            "x": -2,
            "y": -1,
            "z": 2,
            "elements": [
                "xtones:reds@13"
            ]
        },
        {
            "x": -1,
            "y": -1,
            "z": 2,
            "elements": [
                "xtones:reds@6"
            ]
        },
        {
            "x": 0,
            "y": -1,
            "z": 2,
            "elements": [
                "xtones:ztyl@2"
            ]
        },
        {
            "x": 2,
            "y": 3,
            "z": 4,
            "elements": [
                "xtones:reds@5"
            ]
        },
        {
            "x": 1,
            "y": -1,
            "z": 2,
            "elements": [
                "xtones:ztyl@2"
            ]
        },
        {
            "x": 2,
            "y": -1,
            "z": 2,
            "elements": [
                "xtones:reds@13"
            ]
        },
        {
            "x": 1,
            "y": -3,
            "z": 1,
            "elements": [
                "xtones:reds@5"
            ]
        },
        {
            "x": 4,
            "y": 1,
            "z": 3,
            "elements": [
                "bloodmagic:demon_pillar_2@3"
            ]
        },
        {
            "x": 3,
            "y": -1,
            "z": 2,
            "elements": [
                "xtones:reds@14"
            ]
        },
        {
            "x": 4,
            "y": -1,
            "z": 2,
            "elements": [
                "bloodmagic:demon_pillar_2@8"
            ]
        },
        {
            "x": -1,
            "y": -1,
            "z": 10,
            "elements": [
                "xtones:glaxx@11"
            ]
        },
        {
            "x": 1,
            "y": -1,
            "z": 10,
            "elements": [
                "xtones:glaxx@11"
            ]
        },
        {
            "x": 0,
            "y": 16,
            "z": 2,
            "elements": [
                "xtones:reds@15"
            ]
        },
        {
            "x": -2,
            "y": 4,
            "z": 4,
            "elements": [
                "xtones:reds@5"
            ]
        },
        {
            "x": 2,
            "y": 4,
            "z": 4,
            "elements": [
                "xtones:reds@5"
            ]
        },
        {
            "x": -1,
            "y": -2,
            "z": 1,
            "elements": [
                "bloodmagic:demon_pillar_2@13"
            ]
        },
        {
            "x": 1,
            "y": -2,
            "z": 1,
            "elements": [
                "xtones:reds@4"
            ]
        },
        {
            "x": -1,
            "y": -2,
            "z": 9,
            "elements": [
                "bloodmagic:demon_brick_2@13"
            ]
        },
        {
            "x": 0,
            "y": -2,
            "z": 9,
            "elements": [
                "bloodmagic:demon_pillar_2@8"
            ]
        },
        {
            "x": 1,
            "y": -2,
            "z": 9,
            "elements": [
                "bloodmagic:demon_brick_2@13"
            ]
        },
        {
            "x": -1,
            "y": -8,
            "z": 6,
            "elements": [
                "xtones:reds@8"
            ]
        },
        {
            "x": -2,
            "y": 5,
            "z": 4,
            "elements": [
                "xtones:reds@5"
            ]
        },
        {
            "x": -3,
            "y": -1,
            "z": 1,
            "elements": [
                "bloodmagic:demon_brick_2@13"
            ]
        },
        {
            "x": 1,
            "y": -1,
            "z": -2,
            "elements": [
                "xtones:glaxx@11"
            ]
        },
        {
            "x": -2,
            "y": -1,
            "z": 1,
            "elements": [
                "xtones:korp@2"
            ]
        },
        {
            "x": 2,
            "y": 5,
            "z": 4,
            "elements": [
                "xtones:reds@5"
            ]
        },
        {
            "x": 0,
            "y": 1,
            "z": 2,
            "elements": [
                "xtones:zyth@13"
            ]
        },
        {
            "x": -1,
            "y": -1,
            "z": -2,
            "elements": [
                "xtones:glaxx@11"
            ]
        },
        {
            "x": -1,
            "y": -1,
            "z": 1,
            "elements": [
                "xtones:reds@6"
            ]
        },
        {
            "x": 0,
            "y": -1,
            "z": 1,
            "elements": [
                "xtones:reds@14"
            ]
        },
        {
            "x": 1,
            "y": -1,
            "z": 1,
            "elements": [
                "xtones:reds@14"
            ]
        },
        {
            "x": 2,
            "y": -1,
            "z": 1,
            "elements": [
                "xtones:reds@14"
            ]
        },
        {
            "x": 3,
            "y": -1,
            "z": 1,
            "elements": [
                "bloodmagic:demon_brick_2@13"
            ]
        },
        {
            "x": -1,
            "y": -1,
            "z": 9,
            "elements": [
                "xtones:glaxx@11"
            ]
        },
        {
            "x": 1,
            "y": -1,
            "z": 9,
            "elements": [
                "xtones:glaxx@11"
            ]
        },
        {
            "x": -1,
            "y": -7,
            "z": 6,
            "elements": [
                "xtones:reds@5"
            ]
        },
        {
            "x": -2,
            "y": 6,
            "z": 4,
            "elements": [
                "xtones:reds@5"
            ]
        },
        {
            "x": 2,
            "y": 6,
            "z": 4,
            "elements": [
                "xtones:reds@5"
            ]
        },
        {
            "x": 0,
            "y": 2,
            "z": 2,
            "elements": [
                "xtones:reds@5"
            ]
        },
        {
            "x": -1,
            "y": -2,
            "z": 8,
            "elements": [
                "bloodmagic:demon_pillar_2@13"
            ]
        },
        {
            "x": -1,
            "y": -6,
            "z": 6,
            "elements": [
                "xtones:reds@5"
            ]
        },
        {
            "x": 1,
            "y": -2,
            "z": 8,
            "elements": [
                "bloodmagic:demon_pillar_2@13"
            ]
        },
        {
            "x": 2,
            "y": -6,
            "z": 6,
            "elements": [
                "xtones:reds@8"
            ]
        },
        {
            "x": -2,
            "y": 7,
            "z": 4,
            "elements": [
                "xtones:reds@11"
            ]
        },
        {
            "x": 1,
            "y": -1,
            "z": -1,
            "elements": [
                "xtones:glaxx@11"
            ]
        },
        {
            "x": 2,
            "y": 7,
            "z": 4,
            "elements": [
                "xtones:reds@5"
            ]
        },
        {
            "x": 0,
            "y": 3,
            "z": 2,
            "elements": [
                "xtones:reds@5"
            ]
        },
        {
            "x": -1,
            "y": -1,
            "z": -1,
            "elements": [
                "xtones:glaxx@11"
            ]
        },
        {
            "x": -2,
            "y": -1,
            "z": 8,
            "elements": [
                "bloodmagic:demon_pillar_2@13"
            ]
        },
        {
            "x": -1,
            "y": -1,
            "z": 8,
            "elements": [
                "xtones:glaxx@11"
            ]
        },
        {
            "x": 0,
            "y": -1,
            "z": 8,
            "elements": [
                "bloodmagic:demon_brick_2@13"
            ]
        },
        {
            "x": -1,
            "y": -5,
            "z": 6,
            "elements": [
                "xtones:reds@5"
            ]
        },
        {
            "x": 1,
            "y": -1,
            "z": 8,
            "elements": [
                "xtones:glaxx@11"
            ]
        },
        {
            "x": 2,
            "y": -1,
            "z": 8,
            "elements": [
                "bloodmagic:demon_pillar_2@13"
            ]
        },
        {
            "x": 2,
            "y": -5,
            "z": 6,
            "elements": [
                "xtones:reds@5"
            ]
        },
        {
            "x": 1,
            "y": -2,
            "z": -1,
            "elements": [
                "bloodmagic:demon_brick_2@13"
            ]
        },
        {
            "x": 2,
            "y": 8,
            "z": 4,
            "elements": [
                "xtones:reds@5"
            ]
        },
        {
            "x": 0,
            "y": 4,
            "z": 2,
            "elements": [
                "xtones:reds@5"
            ]
        },
        {
            "x": -1,
            "y": -2,
            "z": -1,
            "elements": [
                "bloodmagic:demon_brick_2@13"
            ]
        }
    ]}