
# Created by Ruins mod version 17.1 Ingame Parser
# authoring Player: YiChen_

# depth template is pushed down into the surface when built
# offset is min/max range of random additional bury depth
embed_into_distance=-5
random_height_offset=0,0
unacceptable_target_blocks=flowing_water,water,flowing_lava,lava
# size of template (#layers, #rows per layer, #blocks per row)
dimensions=16,11,11
# depth/height limit affected by terrain leveling
# also maximum bumpiness tolerated in surface beneath template
max_leveling=0

rule1=0,100,tconstruct:seared-7
rule2=0,100,xtones:ztyl-2
rule3=0,100,modularmachinery:blockinputbus-5
rule4=0,100,xtones:bitt-8
rule5=0,100,modularmachinery:blockenergyinputhatch-4
rule6=0,100,contenttweaker:aether_transmuter_1-0
rule7=0,100,modularmachinery:blockfluidinputhatch-5
rule8=0,100,modularmachinery:blockoutputbus-6
rule9=0,100,xtones:korp-15
rule10=0,100,xtones:glaxx-7
rule11=0,100,modularmachinery:blockcontroller-1
rule12=0,100,xtones:zyth-8
rule13=0,100,xtones:azur-6
rule14=0,100,xtones:ztyl-15
rule15=0,100,xtones:azur-9
rule16=0,100,minecraft:iron_bars-0
rule17=0,100,xtones:zech-7

layer
0,0,1,1,0,0,0,1,1,0,0
0,2,2,2,1,3,1,2,2,2,0
1,2,4,2,1,1,1,2,4,2,1
1,2,2,2,1,1,1,2,2,2,1
0,1,1,1,1,1,1,1,1,1,0
0,7,1,1,1,6,1,1,1,5,0
0,1,1,1,1,1,1,1,1,1,0
1,2,2,2,1,1,1,2,2,2,1
1,2,4,2,1,1,1,2,4,2,1
0,2,2,2,1,8,1,2,2,2,0
0,0,1,1,0,0,0,1,1,0,0
endlayer

layer
0,0,0,0,0,0,0,0,0,0,0
0,0,0,9,0,0,0,9,0,0,0
0,0,10,0,0,0,0,0,10,0,0
0,9,0,0,0,0,0,0,0,9,0
0,0,0,0,0,0,0,0,0,0,0
0,0,0,0,0,11,0,0,0,0,0
0,0,0,0,0,0,0,0,0,0,0
0,9,0,0,0,0,0,0,0,9,0
0,0,10,0,0,0,0,0,10,0,0
0,0,0,9,0,0,0,9,0,0,0
0,0,0,0,0,0,0,0,0,0,0
endlayer

layer
0,0,0,0,0,0,0,0,0,0,0
0,0,0,9,0,0,0,9,0,0,0
0,0,10,0,0,0,0,0,10,0,0
0,9,0,0,0,0,0,0,0,9,0
0,0,0,0,10,12,10,0,0,0,0
0,0,0,0,12,13,12,0,0,0,0
0,0,0,0,10,12,10,0,0,0,0
0,9,0,0,0,0,0,0,0,9,0
0,0,10,0,0,0,0,0,10,0,0
0,0,0,9,0,0,0,9,0,0,0
0,0,0,0,0,0,0,0,0,0,0
endlayer

layer
0,0,0,0,0,0,0,0,0,0,0
0,0,0,9,0,0,0,9,0,0,0
0,0,10,0,0,0,0,0,10,0,0
0,9,0,0,0,0,0,0,0,9,0
0,0,0,0,10,10,10,0,0,0,0
0,0,0,0,0,13,0,0,0,0,0
0,0,0,0,10,0,10,0,0,0,0
0,9,0,0,0,0,0,0,0,9,0
0,0,10,0,0,0,0,0,10,0,0
0,0,0,9,0,0,0,9,0,0,0
0,0,0,0,0,0,0,0,0,0,0
endlayer

layer
0,0,0,0,0,0,0,0,0,0,0
0,0,0,9,0,0,0,9,0,0,0
0,0,10,0,0,0,0,0,10,0,0
0,9,0,0,0,0,0,0,0,9,0
0,0,0,0,10,12,10,0,0,0,0
0,0,0,0,12,13,12,0,0,0,0
0,0,0,0,10,12,10,0,0,0,0
0,9,0,0,0,0,0,0,2,2,0
0,0,10,0,0,0,0,2,14,2,0
0,0,0,9,0,0,0,2,2,0,0
0,0,0,0,0,0,0,0,0,0,0
endlayer

layer
0,0,0,0,0,0,0,0,0,0,0
0,0,2,2,0,0,0,9,0,0,0
0,2,14,2,0,0,0,0,10,0,0
0,2,2,0,0,0,0,0,0,9,0
0,0,0,0,10,0,10,0,0,0,0
0,0,0,0,0,13,0,0,0,0,0
0,0,0,0,10,0,10,0,0,0,0
0,9,0,0,0,0,0,0,0,0,0
0,0,10,0,0,0,0,0,0,0,0
0,0,0,9,0,0,0,0,0,0,0
0,0,0,0,0,0,0,0,0,0,0
endlayer

layer
0,0,0,0,0,0,0,0,0,0,0
0,0,0,0,0,0,0,9,0,0,0
0,0,0,0,0,0,0,0,10,0,0
0,0,0,0,0,0,0,0,0,9,0
0,0,0,0,10,12,10,0,0,0,0
0,0,0,0,12,13,12,0,0,0,0
0,0,0,0,10,12,10,0,0,0,0
0,2,2,0,0,0,0,0,0,0,0
0,2,14,2,0,0,0,0,0,0,0
0,0,2,2,0,0,0,0,0,0,0
0,0,0,0,0,0,0,0,0,0,0
endlayer

layer
0,0,0,0,0,0,0,0,0,0,0
0,0,0,0,0,0,0,2,2,0,0
0,0,0,0,0,0,0,2,14,2,0
0,0,0,0,0,0,0,0,2,2,0
0,0,0,0,10,0,10,0,0,0,0
0,0,0,0,0,13,0,0,0,0,0
0,0,0,0,10,0,10,0,0,0,0
0,0,0,0,0,0,0,0,0,0,0
0,0,9,0,0,0,0,0,0,0,0
0,0,0,0,0,0,0,0,0,0,0
0,0,0,0,0,0,0,0,0,0,0
endlayer

layer
0,0,0,0,0,0,0,0,0,0,0
0,0,0,0,0,0,0,0,0,0,0
0,0,0,0,0,0,0,0,9,0,0
0,0,0,0,0,0,0,0,0,0,0
0,0,0,0,10,12,10,0,0,0,0
0,0,0,0,12,13,12,0,0,0,0
0,0,0,0,10,12,10,0,0,0,0
0,0,0,0,0,0,0,0,0,0,0
0,0,9,0,0,0,0,0,0,0,0
0,0,0,0,0,0,0,0,0,0,0
0,0,0,0,0,0,0,0,0,0,0
endlayer

layer
0,0,0,0,0,0,0,0,0,0,0
0,0,0,0,0,0,0,0,0,0,0
0,0,0,0,0,0,0,0,9,0,0
0,0,0,0,0,0,0,0,0,0,0
0,0,0,0,0,0,0,0,0,0,0
0,0,0,0,0,13,0,0,0,0,0
0,0,0,0,0,0,0,0,0,0,0
0,0,0,0,0,0,0,0,0,0,0
0,0,9,0,0,0,0,0,0,0,0
0,0,0,0,0,0,0,0,0,0,0
0,0,0,0,0,0,0,0,0,0,0
endlayer

layer
0,0,0,0,0,0,0,0,0,0,0
0,0,0,0,0,0,0,0,0,0,0
0,0,0,0,0,0,0,0,9,0,0
0,0,0,0,0,14,0,0,0,0,0
0,0,0,0,0,0,0,0,0,0,0
0,0,0,14,0,15,0,14,0,0,0
0,0,0,0,0,0,0,0,0,0,0
0,0,0,0,0,14,0,0,0,0,0
0,0,9,0,0,0,0,0,0,0,0
0,0,0,0,0,0,0,0,0,0,0
0,0,0,0,0,0,0,0,0,0,0
endlayer

layer
0,0,0,0,0,0,0,0,0,0,0
0,0,0,0,0,0,0,0,0,0,0
0,0,0,0,0,9,0,0,9,0,0
0,0,0,2,0,0,0,2,0,0,0
0,0,0,0,0,0,0,0,0,0,0
0,0,9,0,0,0,0,0,9,0,0
0,0,0,0,0,0,0,0,0,0,0
0,0,0,2,0,0,0,2,0,0,0
0,0,9,0,0,9,0,0,0,0,0
0,0,0,0,0,0,0,0,0,0,0
0,0,0,0,0,0,0,0,0,0,0
endlayer

layer
0,0,0,0,0,0,0,0,0,0,0
0,0,0,0,0,0,0,0,0,0,0
0,0,0,0,0,9,0,0,9,0,0
0,0,0,9,0,0,0,9,0,0,0
0,0,0,0,0,0,0,0,0,0,0
0,0,9,0,0,0,0,0,9,0,0
0,0,0,0,0,0,0,0,0,0,0
0,0,0,9,0,0,0,9,0,0,0
0,0,9,0,0,9,0,0,0,0,0
0,0,0,0,0,0,0,0,0,0,0
0,0,0,0,0,0,0,0,0,0,0
endlayer

layer
0,0,0,0,0,0,0,0,0,0,0
0,0,0,0,0,0,0,0,0,0,0
0,0,0,16,16,2,16,16,9,0,0
0,0,16,2,0,16,0,2,16,0,0
0,0,16,0,0,16,0,0,16,0,0
0,0,2,16,16,14,16,16,2,0,0
0,0,16,0,0,16,0,0,16,0,0
0,0,16,2,0,16,0,2,16,0,0
0,0,9,16,16,2,16,16,0,0,0
0,0,0,0,0,0,0,0,0,0,0
0,0,0,0,0,0,0,0,0,0,0
endlayer

layer
0,0,0,0,0,0,0,0,0,0,0
0,0,0,0,1,1,1,0,0,0,0
0,0,0,1,1,1,1,1,9,0,0
0,0,1,1,1,1,1,1,1,0,0
0,1,1,1,1,1,1,1,1,1,0
0,1,1,1,1,1,1,1,1,1,0
0,1,1,1,1,1,1,1,1,1,0
0,0,1,1,1,1,1,1,1,0,0
0,0,9,1,1,1,1,1,0,0,0
0,0,0,0,1,1,1,0,0,0,0
0,0,0,0,0,0,0,0,0,0,0
endlayer

layer
0,0,0,0,0,0,0,0,0,0,0
0,0,0,0,0,0,0,0,0,0,0
0,0,0,0,0,0,0,0,17,0,0
0,0,0,10,10,17,0,4,0,0,0
0,0,0,10,0,0,4,0,0,0,0
0,0,0,17,0,12,0,17,0,0,0
0,0,0,0,4,0,0,10,0,0,0
0,0,0,4,0,17,10,10,0,0,0
0,0,17,0,0,0,0,0,0,0,0
0,0,0,0,0,0,0,0,0,0,0
0,0,0,0,0,0,0,0,0,0,0
endlayer

