
# Created by Ruins mod version 17.1 Ingame Parser
# authoring Player: reydan2

# criterion expression specifying mod ids required to load template
# may include plus (AND), minus (AND NOT), comma (OR), and parentheses
# all required mods listed must be present; no prohibited mods can be
requiredMods=
# likelihood this template will be chosen relative to all others
# e.g., a weight=6 template is chosen 3X as often as one with weight=2
weight=1
# list of other biomes in which this template may spawn
# biome corresponding to directory is always assumed, listed or not
# generic templates should leave this list empty
biomesToSpawnIn=
# criterion expression specifying types of biome where template spawns
# this is in addition to those explicitly listed as biomesToSpawnIn
# generic templates should leave this list empty
biomeTypesToSpawnIn=
# list of biomes in which this template may not spawn
# takes precedence over biomeTypesToSpawnIn, but NOT biomesToSpawnIn
# should be empty if biomeTypesToSpawnIn is empty
biomesToNotSpawnIn=
# depth template is pushed down into the surface when built
# offset is min/max range of random additional bury depth
embed_into_distance=0
random_height_offset=0,0
# whitelist/blacklist of block types on which template may be built
# specify one, not both; leave the other empty (both empty = allow all)
acceptable_target_blocks=
unacceptable_target_blocks=flowing_water,water,flowing_lava,lava
# size of template (#layers, #rows per layer, #blocks per row)
dimensions=16,11,11
# max number of missing blocks allowed in surface beneath template
allowable_overhang=0
# depth/height limit affected by terrain leveling
# also maximum bumpiness tolerated in surface beneath template
max_leveling=2
# padding applied to all sides of template horizontal footprint
# expands area affected by terrain leveling (-1 = no leveling)
leveling_buffer=0
# do not rotate template randomly when built (1 = no rotation)
preventRotation=0
# treat water/lava blocks as air and protect them from rule0 (1 = yes)
preserve_water=0
preserve_lava=0
# minimum distance this template must have from instances of itself
uniqueMinDistance=0
# min/max distances this template can be from world spawn (0 = no limit)
# only applies to overworld--i.e., dimension 0
spawnMinDistance=0
spawnMaxDistance=0
# other template built nearby whenever this one is
# syntax: <name>;<relativeX>;<maxYdifference>;<relativeZ>[;<chance>]
# may be used more than once to specify multiple neighbors
adjoining_template=

rule1=0,100,tconstruct:seared-7
rule2=0,100,xtones:ztyl-2
rule3=0,100,modularmachinery:blockinputbus-5
rule4=0,100,xtones:bitt-8
rule5=0,100,modularmachinery:blockenergyinputhatch-4
rule6=0,100,modularmachinery:blockfluidinputhatch-5
rule7=0,100,modularmachinery:blockoutputbus-6
rule8=0,100,xtones:korp-15
rule9=0,100,xtones:glaxx-7
rule10=0,100,xtones:zech-7
rule11=0,100,xtones:zyth-8
rule12=0,100,xtones:azur-6
rule13=0,100,xtones:ztyl-15
rule14=0,100,xtones:azur-9
rule15=0,100,minecraft:iron_bars-0

layer
0,0,1,1,0,0,0,1,1,0,0
0,2,2,2,1,3,1,2,2,2,0
1,2,4,2,1,1,1,2,4,2,1
1,2,2,2,1,1,1,2,2,2,1
0,1,1,1,1,1,1,1,1,1,0
0,6,1,1,1,1,1,1,1,5,0
0,1,1,1,1,1,1,1,1,1,0
1,2,2,2,1,1,1,2,2,2,1
1,2,4,2,1,1,1,2,4,2,1
0,2,2,2,1,7,1,2,2,2,0
0,0,1,1,0,0,0,1,1,0,0
endlayer

layer
0,0,0,0,0,0,0,0,0,0,0
0,0,0,8,0,0,0,8,0,0,0
0,0,9,0,0,0,0,0,9,0,0
0,8,0,0,0,0,0,0,0,8,0
0,0,0,0,0,0,0,0,0,0,0
0,0,0,0,0,10,0,0,0,0,0
0,0,0,0,0,0,0,0,0,0,0
0,8,0,0,0,0,0,0,0,8,0
0,0,9,0,0,0,0,0,9,0,0
0,0,0,8,0,0,0,8,0,0,0
0,0,0,0,0,0,0,0,0,0,0
endlayer

layer
0,0,0,0,0,0,0,0,0,0,0
0,0,0,8,0,0,0,8,0,0,0
0,0,9,0,0,0,0,0,9,0,0
0,8,0,0,0,0,0,0,0,8,0
0,0,0,0,9,11,9,0,0,0,0
0,0,0,0,11,12,11,0,0,0,0
0,0,0,0,9,11,9,0,0,0,0
0,8,0,0,0,0,0,0,0,8,0
0,0,9,0,0,0,0,0,9,0,0
0,0,0,8,0,0,0,8,0,0,0
0,0,0,0,0,0,0,0,0,0,0
endlayer

layer
0,0,0,0,0,0,0,0,0,0,0
0,0,0,8,0,0,0,8,0,0,0
0,0,9,0,0,0,0,0,9,0,0
0,8,0,0,0,0,0,0,0,8,0
0,0,0,0,9,9,9,0,0,0,0
0,0,0,0,0,12,0,0,0,0,0
0,0,0,0,9,0,9,0,0,0,0
0,8,0,0,0,0,0,0,0,8,0
0,0,9,0,0,0,0,0,9,0,0
0,0,0,8,0,0,0,8,0,0,0
0,0,0,0,0,0,0,0,0,0,0
endlayer

layer
0,0,0,0,0,0,0,0,0,0,0
0,0,0,8,0,0,0,8,0,0,0
0,0,9,0,0,0,0,0,9,0,0
0,8,0,0,0,0,0,0,0,8,0
0,0,0,0,9,11,9,0,0,0,0
0,0,0,0,11,12,11,0,0,0,0
0,0,0,0,9,11,9,0,0,0,0
0,8,0,0,0,0,0,0,2,2,0
0,0,9,0,0,0,0,2,13,2,0
0,0,0,8,0,0,0,2,2,0,0
0,0,0,0,0,0,0,0,0,0,0
endlayer

layer
0,0,0,0,0,0,0,0,0,0,0
0,0,2,2,0,0,0,8,0,0,0
0,2,13,2,0,0,0,0,9,0,0
0,2,2,0,0,0,0,0,0,8,0
0,0,0,0,9,0,9,0,0,0,0
0,0,0,0,0,12,0,0,0,0,0
0,0,0,0,9,0,9,0,0,0,0
0,8,0,0,0,0,0,0,0,0,0
0,0,9,0,0,0,0,0,0,0,0
0,0,0,8,0,0,0,0,0,0,0
0,0,0,0,0,0,0,0,0,0,0
endlayer

layer
0,0,0,0,0,0,0,0,0,0,0
0,0,0,0,0,0,0,8,0,0,0
0,0,0,0,0,0,0,0,9,0,0
0,0,0,0,0,0,0,0,0,8,0
0,0,0,0,9,11,9,0,0,0,0
0,0,0,0,11,12,11,0,0,0,0
0,0,0,0,9,11,9,0,0,0,0
0,2,2,0,0,0,0,0,0,0,0
0,2,13,2,0,0,0,0,0,0,0
0,0,2,2,0,0,0,0,0,0,0
0,0,0,0,0,0,0,0,0,0,0
endlayer

layer
0,0,0,0,0,0,0,0,0,0,0
0,0,0,0,0,0,0,2,2,0,0
0,0,0,0,0,0,0,2,13,2,0
0,0,0,0,0,0,0,0,2,2,0
0,0,0,0,9,0,9,0,0,0,0
0,0,0,0,0,12,0,0,0,0,0
0,0,0,0,9,0,9,0,0,0,0
0,0,0,0,0,0,0,0,0,0,0
0,0,8,0,0,0,0,0,0,0,0
0,0,0,0,0,0,0,0,0,0,0
0,0,0,0,0,0,0,0,0,0,0
endlayer

layer
0,0,0,0,0,0,0,0,0,0,0
0,0,0,0,0,0,0,0,0,0,0
0,0,0,0,0,0,0,0,8,0,0
0,0,0,0,0,0,0,0,0,0,0
0,0,0,0,9,11,9,0,0,0,0
0,0,0,0,11,12,11,0,0,0,0
0,0,0,0,9,11,9,0,0,0,0
0,0,0,0,0,0,0,0,0,0,0
0,0,8,0,0,0,0,0,0,0,0
0,0,0,0,0,0,0,0,0,0,0
0,0,0,0,0,0,0,0,0,0,0
endlayer

layer
0,0,0,0,0,0,0,0,0,0,0
0,0,0,0,0,0,0,0,0,0,0
0,0,0,0,0,0,0,0,8,0,0
0,0,0,0,0,0,0,0,0,0,0
0,0,0,0,0,0,0,0,0,0,0
0,0,0,0,0,12,0,0,0,0,0
0,0,0,0,0,0,0,0,0,0,0
0,0,0,0,0,0,0,0,0,0,0
0,0,8,0,0,0,0,0,0,0,0
0,0,0,0,0,0,0,0,0,0,0
0,0,0,0,0,0,0,0,0,0,0
endlayer

layer
0,0,0,0,0,0,0,0,0,0,0
0,0,0,0,0,0,0,0,0,0,0
0,0,0,0,0,0,0,0,8,0,0
0,0,0,0,0,13,0,0,0,0,0
0,0,0,0,0,0,0,0,0,0,0
0,0,0,13,0,14,0,13,0,0,0
0,0,0,0,0,0,0,0,0,0,0
0,0,0,0,0,13,0,0,0,0,0
0,0,8,0,0,0,0,0,0,0,0
0,0,0,0,0,0,0,0,0,0,0
0,0,0,0,0,0,0,0,0,0,0
endlayer

layer
0,0,0,0,0,0,0,0,0,0,0
0,0,0,0,0,0,0,0,0,0,0
0,0,0,0,0,8,0,0,8,0,0
0,0,0,2,0,0,0,2,0,0,0
0,0,0,0,0,0,0,0,0,0,0
0,0,8,0,0,0,0,0,8,0,0
0,0,0,0,0,0,0,0,0,0,0
0,0,0,2,0,0,0,2,0,0,0
0,0,8,0,0,8,0,0,0,0,0
0,0,0,0,0,0,0,0,0,0,0
0,0,0,0,0,0,0,0,0,0,0
endlayer

layer
0,0,0,0,0,0,0,0,0,0,0
0,0,0,0,0,0,0,0,0,0,0
0,0,0,0,0,8,0,0,8,0,0
0,0,0,8,0,0,0,8,0,0,0
0,0,0,0,0,0,0,0,0,0,0
0,0,8,0,0,0,0,0,8,0,0
0,0,0,0,0,0,0,0,0,0,0
0,0,0,8,0,0,0,8,0,0,0
0,0,8,0,0,8,0,0,0,0,0
0,0,0,0,0,0,0,0,0,0,0
0,0,0,0,0,0,0,0,0,0,0
endlayer

layer
0,0,0,0,0,0,0,0,0,0,0
0,0,0,0,0,0,0,0,0,0,0
0,0,0,15,15,2,15,15,8,0,0
0,0,15,2,0,15,0,2,15,0,0
0,0,15,0,0,15,0,0,15,0,0
0,0,2,15,15,13,15,15,2,0,0
0,0,15,0,0,15,0,0,15,0,0
0,0,15,2,0,15,0,2,15,0,0
0,0,8,15,15,2,15,15,0,0,0
0,0,0,0,0,0,0,0,0,0,0
0,0,0,0,0,0,0,0,0,0,0
endlayer

layer
0,0,0,0,0,0,0,0,0,0,0
0,0,0,0,1,1,1,0,0,0,0
0,0,0,1,1,1,1,1,8,0,0
0,0,1,1,1,1,1,1,1,0,0
0,1,1,1,1,1,1,1,1,1,0
0,1,1,1,1,1,1,1,1,1,0
0,1,1,1,1,1,1,1,1,1,0
0,0,1,1,1,1,1,1,1,0,0
0,0,8,1,1,1,1,1,0,0,0
0,0,0,0,1,1,1,0,0,0,0
0,0,0,0,0,0,0,0,0,0,0
endlayer

layer
0,0,0,0,0,0,0,0,0,0,0
0,0,0,0,0,0,0,0,0,0,0
0,0,0,0,0,0,0,0,10,0,0
0,0,0,9,9,10,0,4,0,0,0
0,0,0,9,0,0,4,0,0,0,0
0,0,0,10,0,11,0,10,0,0,0
0,0,0,0,4,0,0,9,0,0,0
0,0,0,4,0,10,9,9,0,0,0
0,0,10,0,0,0,0,0,0,0,0
0,0,0,0,0,0,0,0,0,0,0
0,0,0,0,0,0,0,0,0,0,0
endlayer

