
# Created by Ruins mod version 17.1 Ingame Parser
# authoring Player: reydan2

# criterion expression specifying mod ids required to load template
# may include plus (AND), minus (AND NOT), comma (OR), and parentheses
# all required mods listed must be present; no prohibited mods can be
requiredMods=
# likelihood this template will be chosen relative to all others
# e.g., a weight=6 template is chosen 3X as often as one with weight=2
weight=1
# list of other biomes in which this template may spawn
# biome corresponding to directory is always assumed, listed or not
# generic templates should leave this list empty
biomesToSpawnIn=
# criterion expression specifying types of biome where template spawns
# this is in addition to those explicitly listed as biomesToSpawnIn
# generic templates should leave this list empty
biomeTypesToSpawnIn=
# list of biomes in which this template may not spawn
# takes precedence over biomeTypesToSpawnIn, but NOT biomesToSpawnIn
# should be empty if biomeTypesToSpawnIn is empty
biomesToNotSpawnIn=
# depth template is pushed down into the surface when built
# offset is min/max range of random additional bury depth
embed_into_distance=-5
random_height_offset=0,0
# whitelist/blacklist of block types on which template may be built
# specify one, not both; leave the other empty (both empty = allow all)
acceptable_target_blocks=
unacceptable_target_blocks=flowing_water,water,flowing_lava,lava
# size of template (#layers, #rows per layer, #blocks per row)
dimensions=20,11,11
# max number of missing blocks allowed in surface beneath template
allowable_overhang=0
# depth/height limit affected by terrain leveling
# also maximum bumpiness tolerated in surface beneath template
max_leveling=0
# padding applied to all sides of template horizontal footprint
# expands area affected by terrain leveling (-1 = no leveling)
leveling_buffer=0
# do not rotate template randomly when built (1 = no rotation)
preventRotation=0
# treat water/lava blocks as air and protect them from rule0 (1 = yes)
preserve_water=0
preserve_lava=0
# minimum distance this template must have from instances of itself
uniqueMinDistance=0
# min/max distances this template can be from world spawn (0 = no limit)
# only applies to overworld--i.e., dimension 0
spawnMinDistance=0
spawnMaxDistance=0
# other template built nearby whenever this one is
# syntax: <name>;<relativeX>;<maxYdifference>;<relativeZ>[;<chance>]
# may be used more than once to specify multiple neighbors
adjoining_template=

rule1=0,100,immersiveengineering:metal_decoration1-0
rule2=0,100,minecraft:cobblestone_wall-0
rule3=0,100,immersiveengineering:metal_decoration1-1
rule4=0,100,chisel:technicalnew-2
rule5=0,100,chisel:factory-1
rule6=0,100,chisel:glass-12
rule7=0,100,modularmachinery:blockfluidoutputhatch-2
rule8=0,100,chisel:factory-3
rule9=0,100,xtones:korp-8
rule10=0,100,modularmachinery:blockfluidinputhatch-2
rule11=0,100,chisel:factory-6
rule12=0,100,quantumstorage:quantum_tank-6
rule13=0,100,immersiveengineering:metal_device1-6
rule14=0,100,quantumstorage:quantum_tank-5
rule15=0,100,xtones:korp-4
rule16=0,100,xtones:zome-15
rule17=0,100,quantumstorage:quantum_tank-7
rule18=0,100,quantumstorage:quantum_tank-4
rule19=0,100,modularmachinery:blockcontroller-1
rule20=0,100,modularmachinery:blockenergyinputhatch-7

layer
0,0,0,0,0,0,0,0,0,0,0
0,0,0,0,0,0,0,0,0,0,0
0,0,0,0,0,0,0,0,0,0,0
0,0,0,0,0,0,0,0,0,0,0
0,0,0,0,0,0,0,0,0,0,0
0,0,0,0,0,0,0,0,0,0,0
0,0,0,0,0,0,0,0,0,0,0
0,0,0,0,0,0,0,0,0,0,0
0,0,0,0,0,0,0,0,0,0,0
0,0,0,0,0,0,0,0,0,0,0
0,0,0,0,0,0,0,0,0,0,0
endlayer

layer
0,0,0,0,0,0,0,0,0,0,0
0,0,0,0,0,0,0,0,0,0,0
0,0,0,0,0,0,0,0,0,0,0
0,0,0,0,0,0,0,0,0,0,0
0,0,0,0,0,0,0,0,0,0,0
0,0,0,0,0,1,0,0,0,0,0
0,0,0,0,0,0,0,0,0,0,0
0,0,0,0,0,0,0,0,0,0,0
0,0,0,0,0,0,0,0,0,0,0
0,0,0,0,0,0,0,0,0,0,0
0,0,0,0,0,0,0,0,0,0,0
endlayer

layer
0,0,0,0,0,0,0,0,0,0,0
0,0,0,0,0,0,0,0,0,0,0
0,0,0,0,0,0,0,0,0,0,0
0,0,0,0,0,0,0,0,0,0,0
0,0,0,0,0,0,0,0,0,0,0
0,0,0,0,0,1,0,0,0,0,0
0,0,0,0,0,0,0,0,0,0,0
0,0,0,0,0,0,0,0,0,0,0
0,0,0,0,0,0,0,0,0,0,0
0,0,0,0,0,0,0,0,0,0,0
0,0,0,0,0,0,0,0,0,0,0
endlayer

layer
0,0,0,0,0,0,0,0,0,0,0
0,0,0,0,0,0,0,0,0,0,0
0,0,0,0,0,0,0,0,0,0,0
0,0,0,0,0,0,0,0,0,0,0
0,0,0,0,0,0,0,0,0,0,0
0,0,0,0,0,2,0,0,0,0,0
0,0,0,0,0,0,0,0,0,0,0
0,0,0,0,0,0,0,0,0,0,0
0,0,0,0,0,0,0,0,0,0,0
0,0,0,0,0,0,0,0,0,0,0
0,0,0,0,0,0,0,0,0,0,0
endlayer

layer
0,0,0,0,0,0,0,0,0,0,0
0,0,0,0,0,0,0,0,0,0,0
0,0,0,0,0,0,0,0,0,0,0
0,0,0,0,0,0,0,0,0,0,0
0,0,0,0,0,0,0,0,0,0,0
0,0,0,0,0,2,0,0,0,0,0
0,0,0,0,0,0,0,0,0,0,0
0,0,0,0,0,0,0,0,0,0,0
0,0,0,0,0,0,0,0,0,0,0
0,0,0,0,0,0,0,0,0,0,0
0,0,0,0,0,0,0,0,0,0,0
endlayer

layer
0,0,0,0,0,0,0,0,0,0,0
0,0,0,0,0,0,0,0,0,0,0
0,0,0,0,0,0,0,0,0,0,0
0,0,0,0,0,0,0,0,0,0,0
0,0,0,0,0,0,0,0,0,0,0
0,0,0,0,0,3,0,0,0,0,0
0,0,0,0,0,0,0,0,0,0,0
0,0,0,0,0,0,0,0,0,0,0
0,0,1,0,0,0,0,0,0,0,0
0,0,0,0,0,0,0,0,0,0,0
0,0,0,0,0,0,0,0,0,0,0
endlayer

layer
0,0,0,0,0,0,0,0,0,0,0
0,0,0,0,0,0,0,0,0,0,0
0,0,1,0,0,0,0,0,0,0,0
0,0,0,0,0,0,0,0,0,0,0
0,0,0,0,0,3,0,0,0,0,0
0,0,0,0,3,3,3,0,0,0,0
0,0,0,0,0,3,0,0,0,0,0
0,0,0,0,0,0,0,0,0,0,0
0,0,1,0,0,0,0,0,1,0,0
0,0,0,0,0,0,0,0,0,0,0
0,0,0,0,0,0,0,0,0,0,0
endlayer

layer
1,0,0,0,0,0,0,0,0,0,1
0,0,0,0,0,0,0,0,0,0,0
0,0,1,0,0,0,0,0,0,0,0
0,0,0,0,0,3,0,0,0,0,0
0,0,0,0,4,5,4,0,0,0,0
0,0,0,3,5,5,5,3,0,0,0
0,0,0,0,4,5,4,0,0,0,0
0,0,0,0,0,3,0,0,0,0,0
0,0,2,0,0,0,0,0,1,0,0
0,0,0,0,0,0,0,0,0,0,0
0,0,1,0,0,0,0,0,1,0,0
endlayer

layer
2,0,1,0,0,0,0,0,0,0,1
0,0,0,0,0,0,0,0,0,0,0
1,0,2,0,0,0,0,0,0,0,0
0,0,0,0,0,5,0,0,0,0,0
0,0,0,0,6,6,6,0,0,0,0
0,0,0,5,6,6,6,5,0,0,0
0,0,0,0,6,6,6,0,0,0,0
0,0,0,0,0,5,0,0,0,0,0
1,0,2,0,0,0,0,0,2,0,1
0,0,0,0,0,0,0,0,0,0,0
1,0,2,0,0,0,0,0,1,0,0
endlayer

layer
3,0,3,0,0,0,0,0,0,0,2
0,0,0,0,0,0,0,0,0,0,0
3,0,3,0,0,0,0,0,1,0,0
0,0,0,0,0,5,0,0,0,0,0
0,0,0,0,0,0,0,0,0,0,0
0,0,0,5,0,7,0,5,0,0,0
0,0,0,0,0,0,0,0,0,0,0
0,0,0,0,0,5,0,0,0,0,0
6,0,6,0,0,0,0,0,2,0,2
0,0,0,0,0,0,0,0,0,0,0
6,0,6,0,0,0,0,0,2,0,1
endlayer

layer
5,3,5,0,0,0,0,0,1,0,2
3,0,3,0,0,0,0,0,0,0,0
5,8,5,0,0,5,0,0,2,0,1
0,0,0,0,0,3,0,0,0,0,0
0,0,0,0,3,3,3,0,0,0,0
0,0,5,3,3,0,3,3,5,0,0
0,0,0,0,3,3,3,0,0,0,0
0,0,0,0,0,3,0,0,0,0,0
6,9,6,0,0,5,0,0,2,0,2
9,0,9,0,0,0,0,0,0,0,0
6,9,6,0,0,0,0,0,2,0,2
endlayer

layer
0,8,0,0,0,0,0,0,3,0,3
8,10,8,0,0,0,0,0,0,0,0
0,8,0,0,0,11,0,0,3,0,3
0,0,0,0,4,4,4,0,0,0,0
0,0,0,4,4,0,4,4,0,0,0
0,0,11,4,0,0,0,4,11,0,0
0,0,5,4,4,0,4,4,0,0,0
0,0,3,0,4,12,4,0,0,0,0
3,8,3,0,0,13,0,0,6,4,6
8,10,13,13,13,13,0,0,4,0,4
3,8,3,0,0,0,0,0,6,4,6
endlayer

layer
0,8,0,0,0,0,0,0,3,6,3
8,13,8,0,0,0,0,0,6,0,6
0,13,0,9,5,6,0,0,3,6,3
0,13,0,0,4,4,4,0,0,0,0
0,13,0,4,4,0,4,4,0,0,0
0,13,13,14,0,0,0,4,6,0,0
0,0,0,4,4,0,4,4,0,0,0
0,0,0,0,4,4,4,0,0,0,0
0,15,0,0,0,6,0,0,6,8,6
15,16,15,0,0,0,0,0,8,10,8
0,15,0,0,0,0,0,0,6,8,6
endlayer

layer
0,11,0,0,0,0,0,0,5,3,5
11,4,11,0,0,13,13,13,13,10,3
0,11,0,0,0,13,0,0,5,3,5
0,0,0,0,4,17,4,0,9,0,0
0,0,0,4,4,0,4,4,5,0,0
0,0,6,4,0,0,0,4,11,0,0
0,0,0,4,4,0,4,4,0,0,0
0,0,0,0,4,4,4,0,0,0,0
0,0,0,0,0,6,0,0,6,8,6
0,0,0,0,0,0,0,0,8,13,8
0,0,0,0,0,0,0,0,6,8,6
endlayer

layer
0,0,0,0,0,0,0,0,0,15,0
0,4,0,0,0,0,0,0,15,16,15
0,0,0,0,0,11,0,0,0,15,0
0,0,0,0,4,4,4,0,0,0,0
0,0,0,4,4,0,4,4,0,0,0
0,0,6,4,0,0,0,18,13,13,0
0,0,0,4,4,0,4,4,0,13,0
0,0,0,0,4,4,4,0,0,13,0
0,0,0,0,0,6,5,3,5,13,5
0,0,0,0,0,0,0,0,3,13,3
0,0,0,0,0,0,0,0,5,3,5
endlayer

layer
0,0,0,0,0,0,0,0,0,0,0
0,0,0,0,0,0,0,0,0,0,0
0,0,0,0,0,11,0,0,0,0,0
0,0,0,0,4,4,4,0,0,0,0
0,0,0,4,4,0,4,4,0,0,0
0,0,11,4,0,0,0,4,11,0,0
0,0,0,4,4,0,4,4,0,0,0
0,0,0,0,4,4,4,0,0,0,0
0,0,0,0,0,11,0,0,0,11,0
0,0,0,0,0,0,0,0,11,4,11
0,0,0,0,0,0,0,0,0,11,0
endlayer

layer
0,0,0,0,0,0,0,0,0,0,0
0,0,0,0,0,0,0,0,0,0,0
0,0,0,0,0,0,0,0,0,0,0
0,0,0,0,0,19,0,0,0,0,0
0,0,0,0,0,5,0,0,0,0,0
0,0,0,5,5,5,5,5,0,0,0
0,0,0,0,0,5,0,0,0,0,0
0,0,0,0,0,5,0,0,0,0,0
0,0,0,0,0,0,0,0,0,0,0
0,0,0,0,0,0,0,0,0,4,0
0,0,0,0,0,0,0,0,0,0,0
endlayer

layer
0,0,0,0,0,0,0,0,0,0,0
0,0,0,0,0,0,0,0,0,0,0
0,0,0,0,0,0,0,0,0,0,0
0,0,0,0,0,0,0,0,0,0,0
0,0,0,0,0,3,0,0,0,0,0
0,0,0,0,3,4,3,0,0,0,0
0,0,0,0,0,3,0,0,0,0,0
0,0,0,0,0,0,0,0,0,0,0
0,0,0,0,0,0,0,0,0,0,0
0,0,0,0,0,0,0,0,0,4,0
0,0,0,0,0,0,0,0,0,0,0
endlayer

layer
0,0,0,0,0,0,0,0,0,0,0
0,0,0,0,0,0,0,0,0,0,0
0,0,0,0,0,0,0,0,0,0,0
0,0,0,0,0,0,0,0,0,0,0
0,0,0,0,0,0,0,0,0,0,0
0,0,0,0,0,20,0,0,0,0,0
0,0,0,0,0,0,0,0,0,0,0
0,0,0,0,0,0,0,0,0,0,0
0,0,0,0,0,0,0,0,0,0,0
0,0,0,0,0,0,0,0,0,0,0
0,0,0,0,0,0,0,0,0,0,0
endlayer

layer
0,0,0,0,0,0,0,0,0,0,0
0,0,0,0,0,0,0,0,0,0,0
0,0,0,0,0,0,0,0,0,0,0
0,0,0,0,0,0,0,0,0,0,0
0,0,0,0,0,0,0,0,0,0,0
0,0,0,0,0,4,0,0,0,0,0
0,0,0,0,0,0,0,0,0,0,0
0,0,0,0,0,0,0,0,0,0,0
0,0,0,0,0,0,0,0,0,0,0
0,0,0,0,0,0,0,0,0,0,0
0,0,0,0,0,0,0,0,0,0,0
endlayer

